2024-03-30T21:54:27 {"cpu": 0.07666015625, "cpu_total": 4, "cpu_usage": 0.0191650390625, "memory": 1444.0, "memory_total": 15986.0, "memory_usage": 0.09032903790816965, "pipeline_run_id": 1, "pipeline_schedule_id": 1, "pipeline_uuid": "etl", "hostname": "ab5b4a0cc6db", "level": "INFO", "message": "Pipeline etl for run 1 in schedule 1 is alive.", "timestamp": 1711835667.906594, "uuid": "3137178bd053401181ec6a6476061ff1"}
2024-03-30T21:54:28 {"cpu": 0.07666015625, "cpu_total": 4, "cpu_usage": 0.0191650390625, "memory": 1468.0, "memory_total": 15986.0, "memory_usage": 0.0918303515576129, "pipeline_run_id": 1, "pipeline_schedule_id": 1, "pipeline_uuid": "etl", "hostname": "ab5b4a0cc6db", "level": "INFO", "message": "Pipeline etl for run 1 in schedule 1 is alive.", "timestamp": 1711835668.016938, "uuid": "97932eed2ea44166abf74713acae44fa"}
2024-03-30T21:54:28 {"block_run_id": 1, "block_uuid": "load_from_api", "pipeline_run_id": 1, "pipeline_schedule_id": 1, "pipeline_uuid": "etl", "hostname": "ab5b4a0cc6db", "level": "INFO", "message": "Execute PipelineRun 1, BlockRun 1: pipeline etl block load_from_api", "timestamp": 1711835668.238547, "uuid": "9da8c5422ebb4fae8cca5f127356d2c3"}
2024-03-30T21:54:37 {"cpu": 0.08740234375, "cpu_total": 4, "cpu_usage": 0.0218505859375, "memory": 1635.0, "memory_total": 15986.0, "memory_usage": 0.10227699236832229, "pipeline_run_id": 1, "pipeline_schedule_id": 1, "pipeline_uuid": "etl", "hostname": "ab5b4a0cc6db", "level": "INFO", "message": "Pipeline etl for run 1 in schedule 1 is alive.", "timestamp": 1711835677.134226, "uuid": "b536ce37a7f54e5f9c1f1c10449d16b2"}
2024-03-30T21:54:47 {"cpu": 0.091796875, "cpu_total": 4, "cpu_usage": 0.02294921875, "memory": 1584.0, "memory_total": 15986.0, "memory_usage": 0.09908670086325534, "pipeline_run_id": 1, "pipeline_schedule_id": 1, "pipeline_uuid": "etl", "hostname": "ab5b4a0cc6db", "level": "INFO", "message": "Pipeline etl for run 1 in schedule 1 is alive.", "timestamp": 1711835687.255376, "uuid": "926a2b22f7394cb8a5379fb331c41df0"}
2024-03-30T21:54:57 {"cpu": 0.09033203125, "cpu_total": 4, "cpu_usage": 0.0225830078125, "memory": 1647.0, "memory_total": 15986.0, "memory_usage": 0.10302764919304391, "pipeline_run_id": 1, "pipeline_schedule_id": 1, "pipeline_uuid": "etl", "hostname": "ab5b4a0cc6db", "level": "INFO", "message": "Pipeline etl for run 1 in schedule 1 is alive.", "timestamp": 1711835697.366662, "uuid": "a317d4fe11fa489d91f26e0dc7a4aa40"}
2024-03-30T21:55:07 {"cpu": 0.08935546875, "cpu_total": 4, "cpu_usage": 0.0223388671875, "memory": 1735.0, "memory_total": 15986.0, "memory_usage": 0.10853246590766921, "pipeline_run_id": 1, "pipeline_schedule_id": 1, "pipeline_uuid": "etl", "hostname": "ab5b4a0cc6db", "level": "INFO", "message": "Pipeline etl for run 1 in schedule 1 is alive.", "timestamp": 1711835707.477174, "uuid": "a6c6f665b1ec4731b2690cec707fa893"}
2024-03-30T21:55:17 {"cpu": 0.08837890625, "cpu_total": 4, "cpu_usage": 0.0220947265625, "memory": 2168.0, "memory_total": 15986.0, "memory_usage": 0.1356186663330414, "pipeline_run_id": 1, "pipeline_schedule_id": 1, "pipeline_uuid": "etl", "hostname": "ab5b4a0cc6db", "level": "INFO", "message": "Pipeline etl for run 1 in schedule 1 is alive.", "timestamp": 1711835717.586703, "uuid": "d84474c14a534cbdb3f4f65331b5fcb3"}
2024-03-30T21:55:19 {"block_run_id": 1, "block_uuid": "load_from_api", "pipeline_run_id": 1, "pipeline_schedule_id": 1, "pipeline_uuid": "etl", "hostname": "ab5b4a0cc6db", "level": "INFO", "message": "BlockRun 1 (block_uuid: load_from_api) completes.", "timestamp": 1711835719.508635, "uuid": "4160be4a70a545a69f144bb9bc3b91d2"}
2024-03-30T21:55:27 {"cpu": 0.0927734375, "cpu_total": 4, "cpu_usage": 0.023193359375, "memory": 1498.0, "memory_total": 15986.0, "memory_usage": 0.09370699361941699, "pipeline_run_id": 1, "pipeline_schedule_id": 1, "pipeline_uuid": "etl", "hostname": "ab5b4a0cc6db", "level": "INFO", "message": "Pipeline etl for run 1 in schedule 1 is alive.", "timestamp": 1711835727.699519, "uuid": "c1bd395b6d284ddab3aa84a2244dc5d3"}
2024-03-30T21:55:27 {"block_run_id": 2, "block_uuid": "transform_data", "pipeline_run_id": 1, "pipeline_schedule_id": 1, "pipeline_uuid": "etl", "hostname": "ab5b4a0cc6db", "level": "INFO", "message": "Execute PipelineRun 1, BlockRun 2: pipeline etl block transform_data", "timestamp": 1711835727.83364, "uuid": "3d7d6462478a4db4b47f13582afa36a9"}
2024-03-30T21:55:37 {"cpu": 0.1025390625, "cpu_total": 4, "cpu_usage": 0.025634765625, "memory": 2347.0, "memory_total": 15986.0, "memory_usage": 0.1468159639684724, "pipeline_run_id": 1, "pipeline_schedule_id": 1, "pipeline_uuid": "etl", "hostname": "ab5b4a0cc6db", "level": "INFO", "message": "Pipeline etl for run 1 in schedule 1 is alive.", "timestamp": 1711835737.851694, "uuid": "f1f4c73ec400434ab09ac3897191f83b"}
2024-03-30T21:55:38 {"block_run_id": 2, "block_uuid": "transform_data", "pipeline_run_id": 1, "pipeline_schedule_id": 1, "pipeline_uuid": "etl", "hostname": "ab5b4a0cc6db", "level": "INFO", "message": "BlockRun 2 (block_uuid: transform_data) completes.", "timestamp": 1711835738.433482, "uuid": "d924bee237c840018fd141cbd2b0b8c2"}
2024-03-30T21:55:47 {"cpu": 0.1005859375, "cpu_total": 4, "cpu_usage": 0.025146484375, "memory": 1483.0, "memory_total": 15986.0, "memory_usage": 0.09276867258851496, "pipeline_run_id": 1, "pipeline_schedule_id": 1, "pipeline_uuid": "etl", "hostname": "ab5b4a0cc6db", "level": "INFO", "message": "Pipeline etl for run 1 in schedule 1 is alive.", "timestamp": 1711835747.96498, "uuid": "45948f79086645849484febb6847ee08"}
2024-03-30T21:55:48 {"block_run_id": 3, "block_uuid": "export_to_gcs", "pipeline_run_id": 1, "pipeline_schedule_id": 1, "pipeline_uuid": "etl", "hostname": "ab5b4a0cc6db", "level": "INFO", "message": "Execute PipelineRun 1, BlockRun 3: pipeline etl block export_to_gcs", "timestamp": 1711835748.095791, "uuid": "a1db8282d44449d781c472f0ac6777fb"}
2024-03-30T21:55:52 {"block_run_id": 3, "block_uuid": "export_to_gcs", "pipeline_run_id": 1, "pipeline_schedule_id": 1, "pipeline_uuid": "etl", "hostname": "ab5b4a0cc6db", "level": "EXCEPTION", "message": "BlockRun 3 (block_uuid: export_to_gcs) failed.", "timestamp": 1711835752.404611, "uuid": "b4993c2c0a33449d97ccbf5fbd716a96", "error": ["Traceback (most recent call last):\n  File \"/usr/local/lib/python3.10/site-packages/mage_ai/data_preparation/executors/block_executor.py\", line 613, in execute\n    result = __execute_with_retry()\n  File \"/usr/local/lib/python3.10/site-packages/mage_ai/shared/retry.py\", line 54, in retry_func\n    raise e\n  File \"/usr/local/lib/python3.10/site-packages/mage_ai/shared/retry.py\", line 38, in retry_func\n    return func(*args, **kwargs)\n  File \"/usr/local/lib/python3.10/site-packages/mage_ai/data_preparation/executors/block_executor.py\", line 588, in __execute_with_retry\n    return self._execute(\n  File \"/usr/local/lib/python3.10/site-packages/mage_ai/data_preparation/executors/block_executor.py\", line 1077, in _execute\n    result = self.block.execute_sync(\n  File \"/usr/local/lib/python3.10/site-packages/mage_ai/data_preparation/models/block/__init__.py\", line 1257, in execute_sync\n    raise err\n  File \"/usr/local/lib/python3.10/site-packages/mage_ai/data_preparation/models/block/__init__.py\", line 1166, in execute_sync\n    output = self.execute_block(\n  File \"/usr/local/lib/python3.10/site-packages/mage_ai/data_preparation/models/block/__init__.py\", line 1472, in execute_block\n    outputs = self._execute_block(\n  File \"/usr/local/lib/python3.10/site-packages/mage_ai/data_preparation/models/block/__init__.py\", line 1628, in _execute_block\n    outputs = self.execute_block_function(\n  File \"/usr/local/lib/python3.10/site-packages/mage_ai/data_preparation/models/block/__init__.py\", line 1667, in execute_block_function\n    output = block_function_updated(*input_vars, **global_vars)\n  File \"<string>\", line 43, in export_data_to_google_cloud_storage\n  File \"/usr/local/lib/python3.10/site-packages/pyarrow/parquet/core.py\", line 3422, in write_to_dataset\n    ds.write_dataset(\n  File \"/usr/local/lib/python3.10/site-packages/pyarrow/dataset.py\", line 1018, in write_dataset\n    _filesystemdataset_write(\n  File \"pyarrow/_dataset.pyx\", line 3919, in pyarrow._dataset._filesystemdataset_write\n  File \"pyarrow/error.pxi\", line 91, in pyarrow.lib.check_status\npyarrow.lib.ArrowInvalid: google::cloud::Status(INVALID_ARGUMENT: Permanent error CreateBucket: Unknown project id:  error_info={reason=invalid, domain=global, metadata={http_status_code=400}}). Detail: [errno 22] Invalid argument\n"], "error_stack": [["  File \"/usr/local/bin/mage\", line 8, in <module>\n    sys.exit(app())\n", "  File \"/usr/local/lib/python3.10/site-packages/typer/main.py\", line 311, in __call__\n    return get_command(self)(*args, **kwargs)\n", "  File \"/usr/local/lib/python3.10/site-packages/click/core.py\", line 1130, in __call__\n    return self.main(*args, **kwargs)\n", "  File \"/usr/local/lib/python3.10/site-packages/typer/core.py\", line 778, in main\n    return _main(\n", "  File \"/usr/local/lib/python3.10/site-packages/typer/core.py\", line 216, in _main\n    rv = self.invoke(ctx)\n", "  File \"/usr/local/lib/python3.10/site-packages/click/core.py\", line 1657, in invoke\n    return _process_result(sub_ctx.command.invoke(sub_ctx))\n", "  File \"/usr/local/lib/python3.10/site-packages/click/core.py\", line 1404, in invoke\n    return ctx.invoke(self.callback, **ctx.params)\n", "  File \"/usr/local/lib/python3.10/site-packages/click/core.py\", line 760, in invoke\n    return __callback(*args, **kwargs)\n", "  File \"/usr/local/lib/python3.10/site-packages/typer/main.py\", line 683, in wrapper\n    return callback(**use_params)  # type: ignore\n", "  File \"/usr/local/lib/python3.10/site-packages/mage_ai/cli/main.py\", line 163, in start\n    start_server(\n", "  File \"/usr/local/lib/python3.10/site-packages/mage_ai/server/server.py\", line 743, in start_server\n    scheduler_manager.start_scheduler()\n", "  File \"/usr/local/lib/python3.10/site-packages/mage_ai/server/scheduler_manager.py\", line 87, in start_scheduler\n    proc.start()\n", "  File \"/usr/local/lib/python3.10/multiprocessing/process.py\", line 121, in start\n    self._popen = self._Popen(self)\n", "  File \"/usr/local/lib/python3.10/multiprocessing/context.py\", line 224, in _Popen\n    return _default_context.get_context().Process._Popen(process_obj)\n", "  File \"/usr/local/lib/python3.10/multiprocessing/context.py\", line 281, in _Popen\n    return Popen(process_obj)\n", "  File \"/usr/local/lib/python3.10/multiprocessing/popen_fork.py\", line 19, in __init__\n    self._launch(process_obj)\n", "  File \"/usr/local/lib/python3.10/multiprocessing/popen_fork.py\", line 71, in _launch\n    code = process_obj._bootstrap(parent_sentinel=child_r)\n", "  File \"/usr/local/lib/python3.10/multiprocessing/process.py\", line 314, in _bootstrap\n    self.run()\n", "  File \"/usr/local/lib/python3.10/multiprocessing/process.py\", line 108, in run\n    self._target(*self._args, **self._kwargs)\n", "  File \"/usr/local/lib/python3.10/site-packages/mage_ai/orchestration/db/process.py\", line 15, in start_session_and_run\n    results = target(*args)\n", "  File \"/usr/local/lib/python3.10/site-packages/mage_ai/server/scheduler_manager.py\", line 50, in run_scheduler\n    LoopTimeTrigger().start()\n", "  File \"/usr/local/lib/python3.10/site-packages/mage_ai/orchestration/triggers/loop_time_trigger.py\", line 14, in start\n    self.run()\n", "  File \"/usr/local/lib/python3.10/site-packages/mage_ai/orchestration/triggers/time_trigger.py\", line 11, in run\n    schedule_all()\n", "  File \"/usr/local/lib/python3.10/site-packages/mage_ai/orchestration/pipeline_scheduler_original.py\", line 1643, in schedule_all\n    PipelineScheduler(r).schedule()\n", "  File \"/usr/local/lib/python3.10/site-packages/mage_ai/orchestration/db/__init__.py\", line 157, in func_with_rollback\n    return func(*args, **kwargs)\n", "  File \"/usr/local/lib/python3.10/site-packages/mage_ai/orchestration/pipeline_scheduler_original.py\", line 318, in schedule\n    self.__schedule_blocks(block_runs)\n", "  File \"/usr/local/lib/python3.10/site-packages/mage_ai/orchestration/pipeline_scheduler_original.py\", line 602, in __schedule_blocks\n    job_manager.add_job(\n", "  File \"/usr/local/lib/python3.10/site-packages/mage_ai/orchestration/job_manager.py\", line 28, in add_job\n    self.queue.enqueue(job_id, target, *args, **kwargs)\n", "  File \"/usr/local/lib/python3.10/site-packages/mage_ai/orchestration/queue/process_queue.py\", line 108, in enqueue\n    self.start_worker_pool()\n", "  File \"/usr/local/lib/python3.10/site-packages/mage_ai/orchestration/queue/process_queue.py\", line 183, in start_worker_pool\n    self.worker_pool_proc.start()\n", "  File \"/usr/local/lib/python3.10/multiprocessing/process.py\", line 121, in start\n    self._popen = self._Popen(self)\n", "  File \"/usr/local/lib/python3.10/multiprocessing/context.py\", line 224, in _Popen\n    return _default_context.get_context().Process._Popen(process_obj)\n", "  File \"/usr/local/lib/python3.10/multiprocessing/context.py\", line 281, in _Popen\n    return Popen(process_obj)\n", "  File \"/usr/local/lib/python3.10/multiprocessing/popen_fork.py\", line 19, in __init__\n    self._launch(process_obj)\n", "  File \"/usr/local/lib/python3.10/multiprocessing/popen_fork.py\", line 71, in _launch\n    code = process_obj._bootstrap(parent_sentinel=child_r)\n", "  File \"/usr/local/lib/python3.10/multiprocessing/process.py\", line 314, in _bootstrap\n    self.run()\n", "  File \"/usr/local/lib/python3.10/multiprocessing/process.py\", line 108, in run\n    self._target(*self._args, **self._kwargs)\n", "  File \"/usr/local/lib/python3.10/site-packages/mage_ai/orchestration/queue/process_queue.py\", line 288, in poll_job_and_execute\n    worker.start()\n", "  File \"/usr/local/lib/python3.10/multiprocessing/process.py\", line 121, in start\n    self._popen = self._Popen(self)\n", "  File \"/usr/local/lib/python3.10/multiprocessing/context.py\", line 224, in _Popen\n    return _default_context.get_context().Process._Popen(process_obj)\n", "  File \"/usr/local/lib/python3.10/multiprocessing/context.py\", line 281, in _Popen\n    return Popen(process_obj)\n", "  File \"/usr/local/lib/python3.10/multiprocessing/popen_fork.py\", line 19, in __init__\n    self._launch(process_obj)\n", "  File \"/usr/local/lib/python3.10/multiprocessing/popen_fork.py\", line 71, in _launch\n    code = process_obj._bootstrap(parent_sentinel=child_r)\n", "  File \"/usr/local/lib/python3.10/multiprocessing/process.py\", line 314, in _bootstrap\n    self.run()\n", "  File \"/usr/local/lib/python3.10/site-packages/newrelic/api/background_task.py\", line 117, in wrapper\n    return wrapped(*args, **kwargs)\n", "  File \"/usr/local/lib/python3.10/site-packages/mage_ai/orchestration/queue/process_queue.py\", line 253, in run\n    start_session_and_run(args[1], *args[2], **args[3])\n", "  File \"/usr/local/lib/python3.10/site-packages/mage_ai/orchestration/db/process.py\", line 15, in start_session_and_run\n    results = target(*args)\n", "  File \"/usr/local/lib/python3.10/site-packages/mage_ai/orchestration/pipeline_scheduler_original.py\", line 1152, in run_block\n    return ExecutorFactory.get_block_executor(\n", "  File \"/usr/local/lib/python3.10/site-packages/mage_ai/data_preparation/executors/block_executor.py\", line 641, in execute\n    on_failure(\n", "  File \"/usr/local/lib/python3.10/site-packages/mage_ai/orchestration/db/__init__.py\", line 157, in func_with_rollback\n    return func(*args, **kwargs)\n", "  File \"/usr/local/lib/python3.10/site-packages/mage_ai/orchestration/pipeline_scheduler_original.py\", line 433, in on_block_failure\n    self.logger.exception(\n", "  File \"/usr/local/lib/python3.10/site-packages/mage_ai/data_preparation/logging/logger.py\", line 30, in exception\n    self.__send_message('exception', message, **kwargs)\n", "  File \"/usr/local/lib/python3.10/site-packages/mage_ai/data_preparation/logging/logger.py\", line 65, in __send_message\n    data['error_stack'] = traceback.format_stack(),\n"]], "error_stacktrace": ["google::cloud::Status(INVALID_ARGUMENT: Permanent error CreateBucket: Unknown project id:  error_info={reason=invalid, domain=global, metadata={http_status_code=400}}). Detail: [errno 22] Invalid argument"]}
Traceback (most recent call last):
  File "/usr/local/lib/python3.10/site-packages/mage_ai/data_preparation/executors/block_executor.py", line 613, in execute
    result = __execute_with_retry()
  File "/usr/local/lib/python3.10/site-packages/mage_ai/shared/retry.py", line 54, in retry_func
    raise e
  File "/usr/local/lib/python3.10/site-packages/mage_ai/shared/retry.py", line 38, in retry_func
    return func(*args, **kwargs)
  File "/usr/local/lib/python3.10/site-packages/mage_ai/data_preparation/executors/block_executor.py", line 588, in __execute_with_retry
    return self._execute(
  File "/usr/local/lib/python3.10/site-packages/mage_ai/data_preparation/executors/block_executor.py", line 1077, in _execute
    result = self.block.execute_sync(
  File "/usr/local/lib/python3.10/site-packages/mage_ai/data_preparation/models/block/__init__.py", line 1257, in execute_sync
    raise err
  File "/usr/local/lib/python3.10/site-packages/mage_ai/data_preparation/models/block/__init__.py", line 1166, in execute_sync
    output = self.execute_block(
  File "/usr/local/lib/python3.10/site-packages/mage_ai/data_preparation/models/block/__init__.py", line 1472, in execute_block
    outputs = self._execute_block(
  File "/usr/local/lib/python3.10/site-packages/mage_ai/data_preparation/models/block/__init__.py", line 1628, in _execute_block
    outputs = self.execute_block_function(
  File "/usr/local/lib/python3.10/site-packages/mage_ai/data_preparation/models/block/__init__.py", line 1667, in execute_block_function
    output = block_function_updated(*input_vars, **global_vars)
  File "<string>", line 43, in export_data_to_google_cloud_storage
  File "/usr/local/lib/python3.10/site-packages/pyarrow/parquet/core.py", line 3422, in write_to_dataset
    ds.write_dataset(
  File "/usr/local/lib/python3.10/site-packages/pyarrow/dataset.py", line 1018, in write_dataset
    _filesystemdataset_write(
  File "pyarrow/_dataset.pyx", line 3919, in pyarrow._dataset._filesystemdataset_write
  File "pyarrow/error.pxi", line 91, in pyarrow.lib.check_status
pyarrow.lib.ArrowInvalid: google::cloud::Status(INVALID_ARGUMENT: Permanent error CreateBucket: Unknown project id:  error_info={reason=invalid, domain=global, metadata={http_status_code=400}}). Detail: [errno 22] Invalid argument
2024-03-30T21:55:57 {"cpu": 0.12060546875, "cpu_total": 4, "cpu_usage": 0.0301513671875, "memory": 1485.0, "memory_total": 15986.0, "memory_usage": 0.09289378205930189, "pipeline_run_id": 1, "pipeline_schedule_id": 1, "pipeline_uuid": "etl", "hostname": "ab5b4a0cc6db", "level": "INFO", "message": "Pipeline etl for run 1 in schedule 1 is alive.", "timestamp": 1711835757.116486, "uuid": "f2ae9e9eaeda4e94b2dde1428d80b3a7"}
