2024-04-01T07:34:44 {"cpu": 0.212890625, "cpu_total": 4, "cpu_usage": 0.05322265625, "memory": 1350.0, "memory_total": 15986.0, "memory_usage": 0.08444889278118353, "pipeline_run_id": 13, "pipeline_schedule_id": 2, "pipeline_uuid": "gcs_to_bigquery", "hostname": "3dbc6f83c5fe", "level": "INFO", "message": "Pipeline gcs_to_bigquery for run 13 in schedule 2 is alive.", "timestamp": 1711956884.547908, "uuid": "ffa8a502f33e44048c1414178c4785e4"}
2024-04-01T07:34:44 {"cpu": 0.212890625, "cpu_total": 4, "cpu_usage": 0.05322265625, "memory": 1373.0, "memory_total": 15986.0, "memory_usage": 0.08588765169523332, "pipeline_run_id": 13, "pipeline_schedule_id": 2, "pipeline_uuid": "gcs_to_bigquery", "hostname": "3dbc6f83c5fe", "level": "INFO", "message": "Pipeline gcs_to_bigquery for run 13 in schedule 2 is alive.", "timestamp": 1711956884.684734, "uuid": "5d4b2665d2fb4b88b2f0e05538117213"}
2024-04-01T07:34:44 {"block_run_id": 37, "block_uuid": "load_from_gcs", "pipeline_run_id": 13, "pipeline_schedule_id": 2, "pipeline_uuid": "gcs_to_bigquery", "hostname": "3dbc6f83c5fe", "level": "INFO", "message": "Execute PipelineRun 13, BlockRun 37: pipeline gcs_to_bigquery block load_from_gcs", "timestamp": 1711956884.732569, "uuid": "d4b3206453e644d3b3edcd151f7ba2f8"}
2024-04-01T07:34:47 {"block_run_id": 37, "block_uuid": "load_from_gcs", "pipeline_run_id": 13, "pipeline_schedule_id": 2, "pipeline_uuid": "gcs_to_bigquery", "hostname": "3dbc6f83c5fe", "level": "INFO", "message": "BlockRun 37 (block_uuid: load_from_gcs) completes.", "timestamp": 1711956887.378507, "uuid": "0b4c8fd9296e421d9a0c63a16dfe50a9"}
2024-04-01T07:34:54 {"cpu": 0.2158203125, "cpu_total": 4, "cpu_usage": 0.053955078125, "memory": 1325.0, "memory_total": 15986.0, "memory_usage": 0.0828850243963468, "pipeline_run_id": 13, "pipeline_schedule_id": 2, "pipeline_uuid": "gcs_to_bigquery", "hostname": "3dbc6f83c5fe", "level": "INFO", "message": "Pipeline gcs_to_bigquery for run 13 in schedule 2 is alive.", "timestamp": 1711956894.880201, "uuid": "87ceb9ae7d444d0fb9a5c606018331ef"}
2024-04-01T07:34:55 {"block_run_id": 38, "block_uuid": "transform_the_data", "pipeline_run_id": 13, "pipeline_schedule_id": 2, "pipeline_uuid": "gcs_to_bigquery", "hostname": "3dbc6f83c5fe", "level": "INFO", "message": "Execute PipelineRun 13, BlockRun 38: pipeline gcs_to_bigquery block transform_the_data", "timestamp": 1711956895.057148, "uuid": "48c577e5cfd243869558ec5da75b3e46"}
2024-04-01T07:35:05 {"cpu": 0.24072265625, "cpu_total": 4, "cpu_usage": 0.0601806640625, "memory": 2165.0, "memory_total": 15986.0, "memory_usage": 0.13543100212686102, "pipeline_run_id": 13, "pipeline_schedule_id": 2, "pipeline_uuid": "gcs_to_bigquery", "hostname": "3dbc6f83c5fe", "level": "INFO", "message": "Pipeline gcs_to_bigquery for run 13 in schedule 2 is alive.", "timestamp": 1711956905.116436, "uuid": "05db74c3e6784cb78deb2f928e785856"}
2024-04-01T07:35:06 {"block_run_id": 38, "block_uuid": "transform_the_data", "pipeline_run_id": 13, "pipeline_schedule_id": 2, "pipeline_uuid": "gcs_to_bigquery", "hostname": "3dbc6f83c5fe", "level": "INFO", "message": "BlockRun 38 (block_uuid: transform_the_data) completes.", "timestamp": 1711956906.267586, "uuid": "2b8a770e71c844a1bb4cba007b571578"}
2024-04-01T07:35:14 {"cpu": 0.24365234375, "cpu_total": 4, "cpu_usage": 0.0609130859375, "memory": 1337.0, "memory_total": 15986.0, "memory_usage": 0.08363568122106843, "pipeline_run_id": 13, "pipeline_schedule_id": 2, "pipeline_uuid": "gcs_to_bigquery", "hostname": "3dbc6f83c5fe", "level": "INFO", "message": "Pipeline gcs_to_bigquery for run 13 in schedule 2 is alive.", "timestamp": 1711956914.2897, "uuid": "f48c173d61374d88acc7fd9ba8bd5f22"}
2024-04-01T07:35:14 {"block_run_id": 39, "block_uuid": "write_to_bigquery", "pipeline_run_id": 13, "pipeline_schedule_id": 2, "pipeline_uuid": "gcs_to_bigquery", "hostname": "3dbc6f83c5fe", "level": "INFO", "message": "Execute PipelineRun 13, BlockRun 39: pipeline gcs_to_bigquery block write_to_bigquery", "timestamp": 1711956914.468039, "uuid": "6955ce65247b4ddcbe25729d1a8977a9"}
2024-04-01T07:35:17 {"block_run_id": 39, "block_uuid": "write_to_bigquery", "pipeline_run_id": 13, "pipeline_schedule_id": 2, "pipeline_uuid": "gcs_to_bigquery", "hostname": "3dbc6f83c5fe", "level": "EXCEPTION", "message": "BlockRun 39 (block_uuid: write_to_bigquery) failed.", "timestamp": 1711956917.736411, "uuid": "edc21a2cf78d44cdb858d0613a2888f1", "error": ["Traceback (most recent call last):\n  File \"/usr/local/lib/python3.10/site-packages/mage_ai/data_preparation/executors/block_executor.py\", line 613, in execute\n    result = __execute_with_retry()\n  File \"/usr/local/lib/python3.10/site-packages/mage_ai/shared/retry.py\", line 54, in retry_func\n    raise e\n  File \"/usr/local/lib/python3.10/site-packages/mage_ai/shared/retry.py\", line 38, in retry_func\n    return func(*args, **kwargs)\n  File \"/usr/local/lib/python3.10/site-packages/mage_ai/data_preparation/executors/block_executor.py\", line 588, in __execute_with_retry\n    return self._execute(\n  File \"/usr/local/lib/python3.10/site-packages/mage_ai/data_preparation/executors/block_executor.py\", line 1077, in _execute\n    result = self.block.execute_sync(\n  File \"/usr/local/lib/python3.10/site-packages/mage_ai/data_preparation/models/block/__init__.py\", line 1257, in execute_sync\n    raise err\n  File \"/usr/local/lib/python3.10/site-packages/mage_ai/data_preparation/models/block/__init__.py\", line 1166, in execute_sync\n    output = self.execute_block(\n  File \"/usr/local/lib/python3.10/site-packages/mage_ai/data_preparation/models/block/__init__.py\", line 1472, in execute_block\n    outputs = self._execute_block(\n  File \"/usr/local/lib/python3.10/site-packages/mage_ai/data_preparation/models/block/sql/__init__.py\", line 721, in _execute_block\n    return execute_sql_code(\n  File \"/usr/local/lib/python3.10/site-packages/mage_ai/data_preparation/models/block/sql/__init__.py\", line 159, in execute_sql_code\n    not is_dynamic and bigquery.create_upstream_block_tables(\n  File \"/usr/local/lib/python3.10/site-packages/mage_ai/data_preparation/models/block/sql/bigquery.py\", line 113, in create_upstream_block_tables\n    loader.export(\n  File \"/usr/local/lib/python3.10/site-packages/mage_ai/io/bigquery.py\", line 323, in export\n    __process(database=database)\n  File \"/usr/local/lib/python3.10/site-packages/mage_ai/io/bigquery.py\", line 296, in __process\n    column_types = self.get_column_types(schema, table_name)\n  File \"/usr/local/lib/python3.10/site-packages/mage_ai/io/bigquery.py\", line 93, in get_column_types\n    for col, col_type in results:\n  File \"/usr/local/lib/python3.10/site-packages/google/cloud/bigquery/job/query.py\", line 1994, in __iter__\n    return iter(self.result())\n  File \"/usr/local/lib/python3.10/site-packages/google/cloud/bigquery/job/query.py\", line 1595, in result\n    do_get_result()\n  File \"/usr/local/lib/python3.10/site-packages/google/api_core/retry.py\", line 372, in retry_wrapped_func\n    return retry_target(\n  File \"/usr/local/lib/python3.10/site-packages/google/api_core/retry.py\", line 207, in retry_target\n    result = target()\n  File \"/usr/local/lib/python3.10/site-packages/google/cloud/bigquery/job/query.py\", line 1584, in do_get_result\n    super(QueryJob, self).result(retry=retry, timeout=timeout)\n  File \"/usr/local/lib/python3.10/site-packages/google/cloud/bigquery/job/base.py\", line 952, in result\n    return super(_AsyncJob, self).result(timeout=timeout, **kwargs)\n  File \"/usr/local/lib/python3.10/site-packages/google/api_core/future/polling.py\", line 261, in result\n    raise self._exception\ngoogle.api_core.exceptions.NotFound: 404 Not found: Dataset snappy-catcher-418306:employee_data was not found in location EU\n\nLocation: EU\nJob ID: 1cdc8153-6ebc-4d0d-8ff9-54989e955a80\n\n"], "error_stack": [["  File \"/usr/local/bin/mage\", line 8, in <module>\n    sys.exit(app())\n", "  File \"/usr/local/lib/python3.10/site-packages/typer/main.py\", line 311, in __call__\n    return get_command(self)(*args, **kwargs)\n", "  File \"/usr/local/lib/python3.10/site-packages/click/core.py\", line 1130, in __call__\n    return self.main(*args, **kwargs)\n", "  File \"/usr/local/lib/python3.10/site-packages/typer/core.py\", line 778, in main\n    return _main(\n", "  File \"/usr/local/lib/python3.10/site-packages/typer/core.py\", line 216, in _main\n    rv = self.invoke(ctx)\n", "  File \"/usr/local/lib/python3.10/site-packages/click/core.py\", line 1657, in invoke\n    return _process_result(sub_ctx.command.invoke(sub_ctx))\n", "  File \"/usr/local/lib/python3.10/site-packages/click/core.py\", line 1404, in invoke\n    return ctx.invoke(self.callback, **ctx.params)\n", "  File \"/usr/local/lib/python3.10/site-packages/click/core.py\", line 760, in invoke\n    return __callback(*args, **kwargs)\n", "  File \"/usr/local/lib/python3.10/site-packages/typer/main.py\", line 683, in wrapper\n    return callback(**use_params)  # type: ignore\n", "  File \"/usr/local/lib/python3.10/site-packages/mage_ai/cli/main.py\", line 163, in start\n    start_server(\n", "  File \"/usr/local/lib/python3.10/site-packages/mage_ai/server/server.py\", line 743, in start_server\n    scheduler_manager.start_scheduler()\n", "  File \"/usr/local/lib/python3.10/site-packages/mage_ai/server/scheduler_manager.py\", line 87, in start_scheduler\n    proc.start()\n", "  File \"/usr/local/lib/python3.10/multiprocessing/process.py\", line 121, in start\n    self._popen = self._Popen(self)\n", "  File \"/usr/local/lib/python3.10/multiprocessing/context.py\", line 224, in _Popen\n    return _default_context.get_context().Process._Popen(process_obj)\n", "  File \"/usr/local/lib/python3.10/multiprocessing/context.py\", line 281, in _Popen\n    return Popen(process_obj)\n", "  File \"/usr/local/lib/python3.10/multiprocessing/popen_fork.py\", line 19, in __init__\n    self._launch(process_obj)\n", "  File \"/usr/local/lib/python3.10/multiprocessing/popen_fork.py\", line 71, in _launch\n    code = process_obj._bootstrap(parent_sentinel=child_r)\n", "  File \"/usr/local/lib/python3.10/multiprocessing/process.py\", line 314, in _bootstrap\n    self.run()\n", "  File \"/usr/local/lib/python3.10/multiprocessing/process.py\", line 108, in run\n    self._target(*self._args, **self._kwargs)\n", "  File \"/usr/local/lib/python3.10/site-packages/mage_ai/orchestration/db/process.py\", line 15, in start_session_and_run\n    results = target(*args)\n", "  File \"/usr/local/lib/python3.10/site-packages/mage_ai/server/scheduler_manager.py\", line 50, in run_scheduler\n    LoopTimeTrigger().start()\n", "  File \"/usr/local/lib/python3.10/site-packages/mage_ai/orchestration/triggers/loop_time_trigger.py\", line 14, in start\n    self.run()\n", "  File \"/usr/local/lib/python3.10/site-packages/mage_ai/orchestration/triggers/time_trigger.py\", line 11, in run\n    schedule_all()\n", "  File \"/usr/local/lib/python3.10/site-packages/mage_ai/orchestration/pipeline_scheduler_original.py\", line 1652, in schedule_all\n    PipelineScheduler(r).schedule()\n", "  File \"/usr/local/lib/python3.10/site-packages/mage_ai/orchestration/db/__init__.py\", line 157, in func_with_rollback\n    return func(*args, **kwargs)\n", "  File \"/usr/local/lib/python3.10/site-packages/mage_ai/orchestration/pipeline_scheduler_original.py\", line 318, in schedule\n    self.__schedule_blocks(block_runs)\n", "  File \"/usr/local/lib/python3.10/site-packages/mage_ai/orchestration/pipeline_scheduler_original.py\", line 611, in __schedule_blocks\n    job_manager.add_job(\n", "  File \"/usr/local/lib/python3.10/site-packages/mage_ai/orchestration/job_manager.py\", line 28, in add_job\n    self.queue.enqueue(job_id, target, *args, **kwargs)\n", "  File \"/usr/local/lib/python3.10/site-packages/mage_ai/orchestration/queue/process_queue.py\", line 108, in enqueue\n    self.start_worker_pool()\n", "  File \"/usr/local/lib/python3.10/site-packages/mage_ai/orchestration/queue/process_queue.py\", line 183, in start_worker_pool\n    self.worker_pool_proc.start()\n", "  File \"/usr/local/lib/python3.10/multiprocessing/process.py\", line 121, in start\n    self._popen = self._Popen(self)\n", "  File \"/usr/local/lib/python3.10/multiprocessing/context.py\", line 224, in _Popen\n    return _default_context.get_context().Process._Popen(process_obj)\n", "  File \"/usr/local/lib/python3.10/multiprocessing/context.py\", line 281, in _Popen\n    return Popen(process_obj)\n", "  File \"/usr/local/lib/python3.10/multiprocessing/popen_fork.py\", line 19, in __init__\n    self._launch(process_obj)\n", "  File \"/usr/local/lib/python3.10/multiprocessing/popen_fork.py\", line 71, in _launch\n    code = process_obj._bootstrap(parent_sentinel=child_r)\n", "  File \"/usr/local/lib/python3.10/multiprocessing/process.py\", line 314, in _bootstrap\n    self.run()\n", "  File \"/usr/local/lib/python3.10/multiprocessing/process.py\", line 108, in run\n    self._target(*self._args, **self._kwargs)\n", "  File \"/usr/local/lib/python3.10/site-packages/mage_ai/orchestration/queue/process_queue.py\", line 288, in poll_job_and_execute\n    worker.start()\n", "  File \"/usr/local/lib/python3.10/multiprocessing/process.py\", line 121, in start\n    self._popen = self._Popen(self)\n", "  File \"/usr/local/lib/python3.10/multiprocessing/context.py\", line 224, in _Popen\n    return _default_context.get_context().Process._Popen(process_obj)\n", "  File \"/usr/local/lib/python3.10/multiprocessing/context.py\", line 281, in _Popen\n    return Popen(process_obj)\n", "  File \"/usr/local/lib/python3.10/multiprocessing/popen_fork.py\", line 19, in __init__\n    self._launch(process_obj)\n", "  File \"/usr/local/lib/python3.10/multiprocessing/popen_fork.py\", line 71, in _launch\n    code = process_obj._bootstrap(parent_sentinel=child_r)\n", "  File \"/usr/local/lib/python3.10/multiprocessing/process.py\", line 314, in _bootstrap\n    self.run()\n", "  File \"/usr/local/lib/python3.10/site-packages/newrelic/api/background_task.py\", line 117, in wrapper\n    return wrapped(*args, **kwargs)\n", "  File \"/usr/local/lib/python3.10/site-packages/mage_ai/orchestration/queue/process_queue.py\", line 253, in run\n    start_session_and_run(args[1], *args[2], **args[3])\n", "  File \"/usr/local/lib/python3.10/site-packages/mage_ai/orchestration/db/process.py\", line 15, in start_session_and_run\n    results = target(*args)\n", "  File \"/usr/local/lib/python3.10/site-packages/mage_ai/orchestration/pipeline_scheduler_original.py\", line 1161, in run_block\n    return ExecutorFactory.get_block_executor(\n", "  File \"/usr/local/lib/python3.10/site-packages/mage_ai/data_preparation/executors/block_executor.py\", line 641, in execute\n    on_failure(\n", "  File \"/usr/local/lib/python3.10/site-packages/mage_ai/orchestration/db/__init__.py\", line 157, in func_with_rollback\n    return func(*args, **kwargs)\n", "  File \"/usr/local/lib/python3.10/site-packages/mage_ai/orchestration/pipeline_scheduler_original.py\", line 442, in on_block_failure\n    self.logger.exception(\n", "  File \"/usr/local/lib/python3.10/site-packages/mage_ai/data_preparation/logging/logger.py\", line 30, in exception\n    self.__send_message('exception', message, **kwargs)\n", "  File \"/usr/local/lib/python3.10/site-packages/mage_ai/data_preparation/logging/logger.py\", line 65, in __send_message\n    data['error_stack'] = traceback.format_stack(),\n"]], "error_stacktrace": ["404 Not found: Dataset snappy-catcher-418306:employee_data was not found in location EU\n\nLocation: EU\nJob ID: 1cdc8153-6ebc-4d0d-8ff9-54989e955a80\n"]}
Traceback (most recent call last):
  File "/usr/local/lib/python3.10/site-packages/mage_ai/data_preparation/executors/block_executor.py", line 613, in execute
    result = __execute_with_retry()
  File "/usr/local/lib/python3.10/site-packages/mage_ai/shared/retry.py", line 54, in retry_func
    raise e
  File "/usr/local/lib/python3.10/site-packages/mage_ai/shared/retry.py", line 38, in retry_func
    return func(*args, **kwargs)
  File "/usr/local/lib/python3.10/site-packages/mage_ai/data_preparation/executors/block_executor.py", line 588, in __execute_with_retry
    return self._execute(
  File "/usr/local/lib/python3.10/site-packages/mage_ai/data_preparation/executors/block_executor.py", line 1077, in _execute
    result = self.block.execute_sync(
  File "/usr/local/lib/python3.10/site-packages/mage_ai/data_preparation/models/block/__init__.py", line 1257, in execute_sync
    raise err
  File "/usr/local/lib/python3.10/site-packages/mage_ai/data_preparation/models/block/__init__.py", line 1166, in execute_sync
    output = self.execute_block(
  File "/usr/local/lib/python3.10/site-packages/mage_ai/data_preparation/models/block/__init__.py", line 1472, in execute_block
    outputs = self._execute_block(
  File "/usr/local/lib/python3.10/site-packages/mage_ai/data_preparation/models/block/sql/__init__.py", line 721, in _execute_block
    return execute_sql_code(
  File "/usr/local/lib/python3.10/site-packages/mage_ai/data_preparation/models/block/sql/__init__.py", line 159, in execute_sql_code
    not is_dynamic and bigquery.create_upstream_block_tables(
  File "/usr/local/lib/python3.10/site-packages/mage_ai/data_preparation/models/block/sql/bigquery.py", line 113, in create_upstream_block_tables
    loader.export(
  File "/usr/local/lib/python3.10/site-packages/mage_ai/io/bigquery.py", line 323, in export
    __process(database=database)
  File "/usr/local/lib/python3.10/site-packages/mage_ai/io/bigquery.py", line 296, in __process
    column_types = self.get_column_types(schema, table_name)
  File "/usr/local/lib/python3.10/site-packages/mage_ai/io/bigquery.py", line 93, in get_column_types
    for col, col_type in results:
  File "/usr/local/lib/python3.10/site-packages/google/cloud/bigquery/job/query.py", line 1994, in __iter__
    return iter(self.result())
  File "/usr/local/lib/python3.10/site-packages/google/cloud/bigquery/job/query.py", line 1595, in result
    do_get_result()
  File "/usr/local/lib/python3.10/site-packages/google/api_core/retry.py", line 372, in retry_wrapped_func
    return retry_target(
  File "/usr/local/lib/python3.10/site-packages/google/api_core/retry.py", line 207, in retry_target
    result = target()
  File "/usr/local/lib/python3.10/site-packages/google/cloud/bigquery/job/query.py", line 1584, in do_get_result
    super(QueryJob, self).result(retry=retry, timeout=timeout)
  File "/usr/local/lib/python3.10/site-packages/google/cloud/bigquery/job/base.py", line 952, in result
    return super(_AsyncJob, self).result(timeout=timeout, **kwargs)
  File "/usr/local/lib/python3.10/site-packages/google/api_core/future/polling.py", line 261, in result
    raise self._exception
google.api_core.exceptions.NotFound: 404 Not found: Dataset snappy-catcher-418306:employee_data was not found in location EU

Location: EU
Job ID: 1cdc8153-6ebc-4d0d-8ff9-54989e955a80

2024-04-01T07:35:24 {"cpu": 0.24658203125, "cpu_total": 4, "cpu_usage": 0.0616455078125, "memory": 1345.0, "memory_total": 15986.0, "memory_usage": 0.08413611910421619, "pipeline_run_id": 13, "pipeline_schedule_id": 2, "pipeline_uuid": "gcs_to_bigquery", "hostname": "3dbc6f83c5fe", "level": "INFO", "message": "Pipeline gcs_to_bigquery for run 13 in schedule 2 is alive.", "timestamp": 1711956924.520283, "uuid": "b60066a62e304d2fb71013a185733024"}
