2024-04-01T07:35:14 {"block_run_id": 39, "block_uuid": "write_to_bigquery", "pipeline_run_id": 13, "pipeline_schedule_id": 2, "pipeline_uuid": "gcs_to_bigquery", "hostname": "3dbc6f83c5fe", "block_type": "data_exporter", "level": "INFO", "message": "Start executing block with BlockExecutor.", "timestamp": 1711956914.487413, "uuid": "968c50b33ff4449ea6eee6a09cdb3db7"}
2024-04-01T07:35:15 {"block_run_id": 39, "block_uuid": "write_to_bigquery", "pipeline_run_id": 13, "pipeline_schedule_id": 2, "pipeline_uuid": "gcs_to_bigquery", "hostname": "3dbc6f83c5fe", "block_type": "data_exporter", "level": "INFO", "message": "BigQuery initialized", "timestamp": 1711956915.535604, "uuid": "9d9f26ee72004b11867ad6ed20e434cb"}
2024-04-01T07:35:15 {"block_run_id": 39, "block_uuid": "write_to_bigquery", "pipeline_run_id": 13, "pipeline_schedule_id": 2, "pipeline_uuid": "gcs_to_bigquery", "hostname": "3dbc6f83c5fe", "block_type": "data_exporter", "level": "INFO", "message": "\u2514\u2500 Connecting to BigQuery warehouse...", "timestamp": 1711956915.587809, "uuid": "2ce04a4a065449798a03fb90fdcc21aa"}
2024-04-01T07:35:15 {"block_run_id": 39, "block_uuid": "write_to_bigquery", "pipeline_run_id": 13, "pipeline_schedule_id": 2, "pipeline_uuid": "gcs_to_bigquery", "hostname": "3dbc6f83c5fe", "block_type": "data_exporter", "level": "INFO", "message": "DONE", "timestamp": 1711956915.588335, "uuid": "7f1316c146654c80aa543f7b8ee3ffc6"}
2024-04-01T07:35:15 {"block_run_id": 39, "block_uuid": "write_to_bigquery", "pipeline_run_id": 13, "pipeline_schedule_id": 2, "pipeline_uuid": "gcs_to_bigquery", "hostname": "3dbc6f83c5fe", "block_type": "data_exporter", "level": "INFO", "message": "", "timestamp": 1711956915.862199, "uuid": "724d0dd14f634227b08ba9694dad33f2"}
2024-04-01T07:35:15 {"block_run_id": 39, "block_uuid": "write_to_bigquery", "pipeline_run_id": 13, "pipeline_schedule_id": 2, "pipeline_uuid": "gcs_to_bigquery", "hostname": "3dbc6f83c5fe", "block_type": "data_exporter", "level": "INFO", "message": "", "timestamp": 1711956915.86258, "uuid": "979ab43dcbd942bc9005aa333413e194"}
2024-04-01T07:35:15 {"block_run_id": 39, "block_uuid": "write_to_bigquery", "pipeline_run_id": 13, "pipeline_schedule_id": 2, "pipeline_uuid": "gcs_to_bigquery", "hostname": "3dbc6f83c5fe", "block_type": "data_exporter", "level": "INFO", "message": "Exporting data from upstream block transform_the_data to snappy-catcher-418306.employee_data.gcs_to_bigquery_transform_the_data_v1.", "timestamp": 1711956915.862745, "uuid": "721723dfd0b54b2e8581ea752ad19e46"}
2024-04-01T07:35:17 {"block_run_id": 39, "block_uuid": "write_to_bigquery", "pipeline_run_id": 13, "pipeline_schedule_id": 2, "pipeline_uuid": "gcs_to_bigquery", "hostname": "3dbc6f83c5fe", "block_type": "data_exporter", "level": "WARNING", "message": "Exception thrown when attempting to run <function BlockExecutor.execute.<locals>.__execute_with_retry at 0x7f814d3d44c0>, attempt 1 of 1", "timestamp": 1711956917.069454, "uuid": "83d91fb4b2bd4f3b91ed47a5127e5846", "error": ["Traceback (most recent call last):\n  File \"/usr/local/lib/python3.10/site-packages/mage_ai/shared/retry.py\", line 38, in retry_func\n    return func(*args, **kwargs)\n  File \"/usr/local/lib/python3.10/site-packages/mage_ai/data_preparation/executors/block_executor.py\", line 588, in __execute_with_retry\n    return self._execute(\n  File \"/usr/local/lib/python3.10/site-packages/mage_ai/data_preparation/executors/block_executor.py\", line 1077, in _execute\n    result = self.block.execute_sync(\n  File \"/usr/local/lib/python3.10/site-packages/mage_ai/data_preparation/models/block/__init__.py\", line 1257, in execute_sync\n    raise err\n  File \"/usr/local/lib/python3.10/site-packages/mage_ai/data_preparation/models/block/__init__.py\", line 1166, in execute_sync\n    output = self.execute_block(\n  File \"/usr/local/lib/python3.10/site-packages/mage_ai/data_preparation/models/block/__init__.py\", line 1472, in execute_block\n    outputs = self._execute_block(\n  File \"/usr/local/lib/python3.10/site-packages/mage_ai/data_preparation/models/block/sql/__init__.py\", line 721, in _execute_block\n    return execute_sql_code(\n  File \"/usr/local/lib/python3.10/site-packages/mage_ai/data_preparation/models/block/sql/__init__.py\", line 159, in execute_sql_code\n    not is_dynamic and bigquery.create_upstream_block_tables(\n  File \"/usr/local/lib/python3.10/site-packages/mage_ai/data_preparation/models/block/sql/bigquery.py\", line 113, in create_upstream_block_tables\n    loader.export(\n  File \"/usr/local/lib/python3.10/site-packages/mage_ai/io/bigquery.py\", line 323, in export\n    __process(database=database)\n  File \"/usr/local/lib/python3.10/site-packages/mage_ai/io/bigquery.py\", line 296, in __process\n    column_types = self.get_column_types(schema, table_name)\n  File \"/usr/local/lib/python3.10/site-packages/mage_ai/io/bigquery.py\", line 93, in get_column_types\n    for col, col_type in results:\n  File \"/usr/local/lib/python3.10/site-packages/google/cloud/bigquery/job/query.py\", line 1994, in __iter__\n    return iter(self.result())\n  File \"/usr/local/lib/python3.10/site-packages/google/cloud/bigquery/job/query.py\", line 1595, in result\n    do_get_result()\n  File \"/usr/local/lib/python3.10/site-packages/google/api_core/retry.py\", line 372, in retry_wrapped_func\n    return retry_target(\n  File \"/usr/local/lib/python3.10/site-packages/google/api_core/retry.py\", line 207, in retry_target\n    result = target()\n  File \"/usr/local/lib/python3.10/site-packages/google/cloud/bigquery/job/query.py\", line 1584, in do_get_result\n    super(QueryJob, self).result(retry=retry, timeout=timeout)\n  File \"/usr/local/lib/python3.10/site-packages/google/cloud/bigquery/job/base.py\", line 952, in result\n    return super(_AsyncJob, self).result(timeout=timeout, **kwargs)\n  File \"/usr/local/lib/python3.10/site-packages/google/api_core/future/polling.py\", line 261, in result\n    raise self._exception\ngoogle.api_core.exceptions.NotFound: 404 Not found: Dataset snappy-catcher-418306:employee_data was not found in location EU\n\nLocation: EU\nJob ID: 1cdc8153-6ebc-4d0d-8ff9-54989e955a80\n\n"], "error_stack": [["  File \"/usr/local/bin/mage\", line 8, in <module>\n    sys.exit(app())\n", "  File \"/usr/local/lib/python3.10/site-packages/typer/main.py\", line 311, in __call__\n    return get_command(self)(*args, **kwargs)\n", "  File \"/usr/local/lib/python3.10/site-packages/click/core.py\", line 1130, in __call__\n    return self.main(*args, **kwargs)\n", "  File \"/usr/local/lib/python3.10/site-packages/typer/core.py\", line 778, in main\n    return _main(\n", "  File \"/usr/local/lib/python3.10/site-packages/typer/core.py\", line 216, in _main\n    rv = self.invoke(ctx)\n", "  File \"/usr/local/lib/python3.10/site-packages/click/core.py\", line 1657, in invoke\n    return _process_result(sub_ctx.command.invoke(sub_ctx))\n", "  File \"/usr/local/lib/python3.10/site-packages/click/core.py\", line 1404, in invoke\n    return ctx.invoke(self.callback, **ctx.params)\n", "  File \"/usr/local/lib/python3.10/site-packages/click/core.py\", line 760, in invoke\n    return __callback(*args, **kwargs)\n", "  File \"/usr/local/lib/python3.10/site-packages/typer/main.py\", line 683, in wrapper\n    return callback(**use_params)  # type: ignore\n", "  File \"/usr/local/lib/python3.10/site-packages/mage_ai/cli/main.py\", line 163, in start\n    start_server(\n", "  File \"/usr/local/lib/python3.10/site-packages/mage_ai/server/server.py\", line 743, in start_server\n    scheduler_manager.start_scheduler()\n", "  File \"/usr/local/lib/python3.10/site-packages/mage_ai/server/scheduler_manager.py\", line 87, in start_scheduler\n    proc.start()\n", "  File \"/usr/local/lib/python3.10/multiprocessing/process.py\", line 121, in start\n    self._popen = self._Popen(self)\n", "  File \"/usr/local/lib/python3.10/multiprocessing/context.py\", line 224, in _Popen\n    return _default_context.get_context().Process._Popen(process_obj)\n", "  File \"/usr/local/lib/python3.10/multiprocessing/context.py\", line 281, in _Popen\n    return Popen(process_obj)\n", "  File \"/usr/local/lib/python3.10/multiprocessing/popen_fork.py\", line 19, in __init__\n    self._launch(process_obj)\n", "  File \"/usr/local/lib/python3.10/multiprocessing/popen_fork.py\", line 71, in _launch\n    code = process_obj._bootstrap(parent_sentinel=child_r)\n", "  File \"/usr/local/lib/python3.10/multiprocessing/process.py\", line 314, in _bootstrap\n    self.run()\n", "  File \"/usr/local/lib/python3.10/multiprocessing/process.py\", line 108, in run\n    self._target(*self._args, **self._kwargs)\n", "  File \"/usr/local/lib/python3.10/site-packages/mage_ai/orchestration/db/process.py\", line 15, in start_session_and_run\n    results = target(*args)\n", "  File \"/usr/local/lib/python3.10/site-packages/mage_ai/server/scheduler_manager.py\", line 50, in run_scheduler\n    LoopTimeTrigger().start()\n", "  File \"/usr/local/lib/python3.10/site-packages/mage_ai/orchestration/triggers/loop_time_trigger.py\", line 14, in start\n    self.run()\n", "  File \"/usr/local/lib/python3.10/site-packages/mage_ai/orchestration/triggers/time_trigger.py\", line 11, in run\n    schedule_all()\n", "  File \"/usr/local/lib/python3.10/site-packages/mage_ai/orchestration/pipeline_scheduler_original.py\", line 1652, in schedule_all\n    PipelineScheduler(r).schedule()\n", "  File \"/usr/local/lib/python3.10/site-packages/mage_ai/orchestration/db/__init__.py\", line 157, in func_with_rollback\n    return func(*args, **kwargs)\n", "  File \"/usr/local/lib/python3.10/site-packages/mage_ai/orchestration/pipeline_scheduler_original.py\", line 318, in schedule\n    self.__schedule_blocks(block_runs)\n", "  File \"/usr/local/lib/python3.10/site-packages/mage_ai/orchestration/pipeline_scheduler_original.py\", line 611, in __schedule_blocks\n    job_manager.add_job(\n", "  File \"/usr/local/lib/python3.10/site-packages/mage_ai/orchestration/job_manager.py\", line 28, in add_job\n    self.queue.enqueue(job_id, target, *args, **kwargs)\n", "  File \"/usr/local/lib/python3.10/site-packages/mage_ai/orchestration/queue/process_queue.py\", line 108, in enqueue\n    self.start_worker_pool()\n", "  File \"/usr/local/lib/python3.10/site-packages/mage_ai/orchestration/queue/process_queue.py\", line 183, in start_worker_pool\n    self.worker_pool_proc.start()\n", "  File \"/usr/local/lib/python3.10/multiprocessing/process.py\", line 121, in start\n    self._popen = self._Popen(self)\n", "  File \"/usr/local/lib/python3.10/multiprocessing/context.py\", line 224, in _Popen\n    return _default_context.get_context().Process._Popen(process_obj)\n", "  File \"/usr/local/lib/python3.10/multiprocessing/context.py\", line 281, in _Popen\n    return Popen(process_obj)\n", "  File \"/usr/local/lib/python3.10/multiprocessing/popen_fork.py\", line 19, in __init__\n    self._launch(process_obj)\n", "  File \"/usr/local/lib/python3.10/multiprocessing/popen_fork.py\", line 71, in _launch\n    code = process_obj._bootstrap(parent_sentinel=child_r)\n", "  File \"/usr/local/lib/python3.10/multiprocessing/process.py\", line 314, in _bootstrap\n    self.run()\n", "  File \"/usr/local/lib/python3.10/multiprocessing/process.py\", line 108, in run\n    self._target(*self._args, **self._kwargs)\n", "  File \"/usr/local/lib/python3.10/site-packages/mage_ai/orchestration/queue/process_queue.py\", line 288, in poll_job_and_execute\n    worker.start()\n", "  File \"/usr/local/lib/python3.10/multiprocessing/process.py\", line 121, in start\n    self._popen = self._Popen(self)\n", "  File \"/usr/local/lib/python3.10/multiprocessing/context.py\", line 224, in _Popen\n    return _default_context.get_context().Process._Popen(process_obj)\n", "  File \"/usr/local/lib/python3.10/multiprocessing/context.py\", line 281, in _Popen\n    return Popen(process_obj)\n", "  File \"/usr/local/lib/python3.10/multiprocessing/popen_fork.py\", line 19, in __init__\n    self._launch(process_obj)\n", "  File \"/usr/local/lib/python3.10/multiprocessing/popen_fork.py\", line 71, in _launch\n    code = process_obj._bootstrap(parent_sentinel=child_r)\n", "  File \"/usr/local/lib/python3.10/multiprocessing/process.py\", line 314, in _bootstrap\n    self.run()\n", "  File \"/usr/local/lib/python3.10/site-packages/newrelic/api/background_task.py\", line 117, in wrapper\n    return wrapped(*args, **kwargs)\n", "  File \"/usr/local/lib/python3.10/site-packages/mage_ai/orchestration/queue/process_queue.py\", line 253, in run\n    start_session_and_run(args[1], *args[2], **args[3])\n", "  File \"/usr/local/lib/python3.10/site-packages/mage_ai/orchestration/db/process.py\", line 15, in start_session_and_run\n    results = target(*args)\n", "  File \"/usr/local/lib/python3.10/site-packages/mage_ai/orchestration/pipeline_scheduler_original.py\", line 1161, in run_block\n    return ExecutorFactory.get_block_executor(\n", "  File \"/usr/local/lib/python3.10/site-packages/mage_ai/data_preparation/executors/block_executor.py\", line 613, in execute\n    result = __execute_with_retry()\n", "  File \"/usr/local/lib/python3.10/site-packages/mage_ai/shared/retry.py\", line 46, in retry_func\n    logger.warning(\n", "  File \"/usr/local/lib/python3.10/site-packages/mage_ai/data_preparation/logging/logger.py\", line 39, in warning\n    self.__send_message('warning', message, **kwargs)\n", "  File \"/usr/local/lib/python3.10/site-packages/mage_ai/data_preparation/logging/logger.py\", line 65, in __send_message\n    data['error_stack'] = traceback.format_stack(),\n"]], "error_stacktrace": ["404 Not found: Dataset snappy-catcher-418306:employee_data was not found in location EU\n\nLocation: EU\nJob ID: 1cdc8153-6ebc-4d0d-8ff9-54989e955a80\n"]}
2024-04-01T07:35:17 {"block_run_id": 39, "block_uuid": "write_to_bigquery", "pipeline_run_id": 13, "pipeline_schedule_id": 2, "pipeline_uuid": "gcs_to_bigquery", "hostname": "3dbc6f83c5fe", "block_type": "data_exporter", "level": "EXCEPTION", "message": "Failed to execute block write_to_bigquery", "timestamp": 1711956917.096679, "uuid": "6f79a73e9536469987805e1fbe42acdb", "error": ["Traceback (most recent call last):\n  File \"/usr/local/lib/python3.10/site-packages/mage_ai/data_preparation/executors/block_executor.py\", line 613, in execute\n    result = __execute_with_retry()\n  File \"/usr/local/lib/python3.10/site-packages/mage_ai/shared/retry.py\", line 54, in retry_func\n    raise e\n  File \"/usr/local/lib/python3.10/site-packages/mage_ai/shared/retry.py\", line 38, in retry_func\n    return func(*args, **kwargs)\n  File \"/usr/local/lib/python3.10/site-packages/mage_ai/data_preparation/executors/block_executor.py\", line 588, in __execute_with_retry\n    return self._execute(\n  File \"/usr/local/lib/python3.10/site-packages/mage_ai/data_preparation/executors/block_executor.py\", line 1077, in _execute\n    result = self.block.execute_sync(\n  File \"/usr/local/lib/python3.10/site-packages/mage_ai/data_preparation/models/block/__init__.py\", line 1257, in execute_sync\n    raise err\n  File \"/usr/local/lib/python3.10/site-packages/mage_ai/data_preparation/models/block/__init__.py\", line 1166, in execute_sync\n    output = self.execute_block(\n  File \"/usr/local/lib/python3.10/site-packages/mage_ai/data_preparation/models/block/__init__.py\", line 1472, in execute_block\n    outputs = self._execute_block(\n  File \"/usr/local/lib/python3.10/site-packages/mage_ai/data_preparation/models/block/sql/__init__.py\", line 721, in _execute_block\n    return execute_sql_code(\n  File \"/usr/local/lib/python3.10/site-packages/mage_ai/data_preparation/models/block/sql/__init__.py\", line 159, in execute_sql_code\n    not is_dynamic and bigquery.create_upstream_block_tables(\n  File \"/usr/local/lib/python3.10/site-packages/mage_ai/data_preparation/models/block/sql/bigquery.py\", line 113, in create_upstream_block_tables\n    loader.export(\n  File \"/usr/local/lib/python3.10/site-packages/mage_ai/io/bigquery.py\", line 323, in export\n    __process(database=database)\n  File \"/usr/local/lib/python3.10/site-packages/mage_ai/io/bigquery.py\", line 296, in __process\n    column_types = self.get_column_types(schema, table_name)\n  File \"/usr/local/lib/python3.10/site-packages/mage_ai/io/bigquery.py\", line 93, in get_column_types\n    for col, col_type in results:\n  File \"/usr/local/lib/python3.10/site-packages/google/cloud/bigquery/job/query.py\", line 1994, in __iter__\n    return iter(self.result())\n  File \"/usr/local/lib/python3.10/site-packages/google/cloud/bigquery/job/query.py\", line 1595, in result\n    do_get_result()\n  File \"/usr/local/lib/python3.10/site-packages/google/api_core/retry.py\", line 372, in retry_wrapped_func\n    return retry_target(\n  File \"/usr/local/lib/python3.10/site-packages/google/api_core/retry.py\", line 207, in retry_target\n    result = target()\n  File \"/usr/local/lib/python3.10/site-packages/google/cloud/bigquery/job/query.py\", line 1584, in do_get_result\n    super(QueryJob, self).result(retry=retry, timeout=timeout)\n  File \"/usr/local/lib/python3.10/site-packages/google/cloud/bigquery/job/base.py\", line 952, in result\n    return super(_AsyncJob, self).result(timeout=timeout, **kwargs)\n  File \"/usr/local/lib/python3.10/site-packages/google/api_core/future/polling.py\", line 261, in result\n    raise self._exception\ngoogle.api_core.exceptions.NotFound: 404 Not found: Dataset snappy-catcher-418306:employee_data was not found in location EU\n\nLocation: EU\nJob ID: 1cdc8153-6ebc-4d0d-8ff9-54989e955a80\n\n"], "error_stack": [["  File \"/usr/local/bin/mage\", line 8, in <module>\n    sys.exit(app())\n", "  File \"/usr/local/lib/python3.10/site-packages/typer/main.py\", line 311, in __call__\n    return get_command(self)(*args, **kwargs)\n", "  File \"/usr/local/lib/python3.10/site-packages/click/core.py\", line 1130, in __call__\n    return self.main(*args, **kwargs)\n", "  File \"/usr/local/lib/python3.10/site-packages/typer/core.py\", line 778, in main\n    return _main(\n", "  File \"/usr/local/lib/python3.10/site-packages/typer/core.py\", line 216, in _main\n    rv = self.invoke(ctx)\n", "  File \"/usr/local/lib/python3.10/site-packages/click/core.py\", line 1657, in invoke\n    return _process_result(sub_ctx.command.invoke(sub_ctx))\n", "  File \"/usr/local/lib/python3.10/site-packages/click/core.py\", line 1404, in invoke\n    return ctx.invoke(self.callback, **ctx.params)\n", "  File \"/usr/local/lib/python3.10/site-packages/click/core.py\", line 760, in invoke\n    return __callback(*args, **kwargs)\n", "  File \"/usr/local/lib/python3.10/site-packages/typer/main.py\", line 683, in wrapper\n    return callback(**use_params)  # type: ignore\n", "  File \"/usr/local/lib/python3.10/site-packages/mage_ai/cli/main.py\", line 163, in start\n    start_server(\n", "  File \"/usr/local/lib/python3.10/site-packages/mage_ai/server/server.py\", line 743, in start_server\n    scheduler_manager.start_scheduler()\n", "  File \"/usr/local/lib/python3.10/site-packages/mage_ai/server/scheduler_manager.py\", line 87, in start_scheduler\n    proc.start()\n", "  File \"/usr/local/lib/python3.10/multiprocessing/process.py\", line 121, in start\n    self._popen = self._Popen(self)\n", "  File \"/usr/local/lib/python3.10/multiprocessing/context.py\", line 224, in _Popen\n    return _default_context.get_context().Process._Popen(process_obj)\n", "  File \"/usr/local/lib/python3.10/multiprocessing/context.py\", line 281, in _Popen\n    return Popen(process_obj)\n", "  File \"/usr/local/lib/python3.10/multiprocessing/popen_fork.py\", line 19, in __init__\n    self._launch(process_obj)\n", "  File \"/usr/local/lib/python3.10/multiprocessing/popen_fork.py\", line 71, in _launch\n    code = process_obj._bootstrap(parent_sentinel=child_r)\n", "  File \"/usr/local/lib/python3.10/multiprocessing/process.py\", line 314, in _bootstrap\n    self.run()\n", "  File \"/usr/local/lib/python3.10/multiprocessing/process.py\", line 108, in run\n    self._target(*self._args, **self._kwargs)\n", "  File \"/usr/local/lib/python3.10/site-packages/mage_ai/orchestration/db/process.py\", line 15, in start_session_and_run\n    results = target(*args)\n", "  File \"/usr/local/lib/python3.10/site-packages/mage_ai/server/scheduler_manager.py\", line 50, in run_scheduler\n    LoopTimeTrigger().start()\n", "  File \"/usr/local/lib/python3.10/site-packages/mage_ai/orchestration/triggers/loop_time_trigger.py\", line 14, in start\n    self.run()\n", "  File \"/usr/local/lib/python3.10/site-packages/mage_ai/orchestration/triggers/time_trigger.py\", line 11, in run\n    schedule_all()\n", "  File \"/usr/local/lib/python3.10/site-packages/mage_ai/orchestration/pipeline_scheduler_original.py\", line 1652, in schedule_all\n    PipelineScheduler(r).schedule()\n", "  File \"/usr/local/lib/python3.10/site-packages/mage_ai/orchestration/db/__init__.py\", line 157, in func_with_rollback\n    return func(*args, **kwargs)\n", "  File \"/usr/local/lib/python3.10/site-packages/mage_ai/orchestration/pipeline_scheduler_original.py\", line 318, in schedule\n    self.__schedule_blocks(block_runs)\n", "  File \"/usr/local/lib/python3.10/site-packages/mage_ai/orchestration/pipeline_scheduler_original.py\", line 611, in __schedule_blocks\n    job_manager.add_job(\n", "  File \"/usr/local/lib/python3.10/site-packages/mage_ai/orchestration/job_manager.py\", line 28, in add_job\n    self.queue.enqueue(job_id, target, *args, **kwargs)\n", "  File \"/usr/local/lib/python3.10/site-packages/mage_ai/orchestration/queue/process_queue.py\", line 108, in enqueue\n    self.start_worker_pool()\n", "  File \"/usr/local/lib/python3.10/site-packages/mage_ai/orchestration/queue/process_queue.py\", line 183, in start_worker_pool\n    self.worker_pool_proc.start()\n", "  File \"/usr/local/lib/python3.10/multiprocessing/process.py\", line 121, in start\n    self._popen = self._Popen(self)\n", "  File \"/usr/local/lib/python3.10/multiprocessing/context.py\", line 224, in _Popen\n    return _default_context.get_context().Process._Popen(process_obj)\n", "  File \"/usr/local/lib/python3.10/multiprocessing/context.py\", line 281, in _Popen\n    return Popen(process_obj)\n", "  File \"/usr/local/lib/python3.10/multiprocessing/popen_fork.py\", line 19, in __init__\n    self._launch(process_obj)\n", "  File \"/usr/local/lib/python3.10/multiprocessing/popen_fork.py\", line 71, in _launch\n    code = process_obj._bootstrap(parent_sentinel=child_r)\n", "  File \"/usr/local/lib/python3.10/multiprocessing/process.py\", line 314, in _bootstrap\n    self.run()\n", "  File \"/usr/local/lib/python3.10/multiprocessing/process.py\", line 108, in run\n    self._target(*self._args, **self._kwargs)\n", "  File \"/usr/local/lib/python3.10/site-packages/mage_ai/orchestration/queue/process_queue.py\", line 288, in poll_job_and_execute\n    worker.start()\n", "  File \"/usr/local/lib/python3.10/multiprocessing/process.py\", line 121, in start\n    self._popen = self._Popen(self)\n", "  File \"/usr/local/lib/python3.10/multiprocessing/context.py\", line 224, in _Popen\n    return _default_context.get_context().Process._Popen(process_obj)\n", "  File \"/usr/local/lib/python3.10/multiprocessing/context.py\", line 281, in _Popen\n    return Popen(process_obj)\n", "  File \"/usr/local/lib/python3.10/multiprocessing/popen_fork.py\", line 19, in __init__\n    self._launch(process_obj)\n", "  File \"/usr/local/lib/python3.10/multiprocessing/popen_fork.py\", line 71, in _launch\n    code = process_obj._bootstrap(parent_sentinel=child_r)\n", "  File \"/usr/local/lib/python3.10/multiprocessing/process.py\", line 314, in _bootstrap\n    self.run()\n", "  File \"/usr/local/lib/python3.10/site-packages/newrelic/api/background_task.py\", line 117, in wrapper\n    return wrapped(*args, **kwargs)\n", "  File \"/usr/local/lib/python3.10/site-packages/mage_ai/orchestration/queue/process_queue.py\", line 253, in run\n    start_session_and_run(args[1], *args[2], **args[3])\n", "  File \"/usr/local/lib/python3.10/site-packages/mage_ai/orchestration/db/process.py\", line 15, in start_session_and_run\n    results = target(*args)\n", "  File \"/usr/local/lib/python3.10/site-packages/mage_ai/orchestration/pipeline_scheduler_original.py\", line 1161, in run_block\n    return ExecutorFactory.get_block_executor(\n", "  File \"/usr/local/lib/python3.10/site-packages/mage_ai/data_preparation/executors/block_executor.py\", line 615, in execute\n    self.logger.exception(\n", "  File \"/usr/local/lib/python3.10/site-packages/mage_ai/data_preparation/logging/logger.py\", line 30, in exception\n    self.__send_message('exception', message, **kwargs)\n", "  File \"/usr/local/lib/python3.10/site-packages/mage_ai/data_preparation/logging/logger.py\", line 65, in __send_message\n    data['error_stack'] = traceback.format_stack(),\n"]], "error_stacktrace": ["404 Not found: Dataset snappy-catcher-418306:employee_data was not found in location EU\n\nLocation: EU\nJob ID: 1cdc8153-6ebc-4d0d-8ff9-54989e955a80\n"]}
Traceback (most recent call last):
  File "/usr/local/lib/python3.10/site-packages/mage_ai/data_preparation/executors/block_executor.py", line 613, in execute
    result = __execute_with_retry()
  File "/usr/local/lib/python3.10/site-packages/mage_ai/shared/retry.py", line 54, in retry_func
    raise e
  File "/usr/local/lib/python3.10/site-packages/mage_ai/shared/retry.py", line 38, in retry_func
    return func(*args, **kwargs)
  File "/usr/local/lib/python3.10/site-packages/mage_ai/data_preparation/executors/block_executor.py", line 588, in __execute_with_retry
    return self._execute(
  File "/usr/local/lib/python3.10/site-packages/mage_ai/data_preparation/executors/block_executor.py", line 1077, in _execute
    result = self.block.execute_sync(
  File "/usr/local/lib/python3.10/site-packages/mage_ai/data_preparation/models/block/__init__.py", line 1257, in execute_sync
    raise err
  File "/usr/local/lib/python3.10/site-packages/mage_ai/data_preparation/models/block/__init__.py", line 1166, in execute_sync
    output = self.execute_block(
  File "/usr/local/lib/python3.10/site-packages/mage_ai/data_preparation/models/block/__init__.py", line 1472, in execute_block
    outputs = self._execute_block(
  File "/usr/local/lib/python3.10/site-packages/mage_ai/data_preparation/models/block/sql/__init__.py", line 721, in _execute_block
    return execute_sql_code(
  File "/usr/local/lib/python3.10/site-packages/mage_ai/data_preparation/models/block/sql/__init__.py", line 159, in execute_sql_code
    not is_dynamic and bigquery.create_upstream_block_tables(
  File "/usr/local/lib/python3.10/site-packages/mage_ai/data_preparation/models/block/sql/bigquery.py", line 113, in create_upstream_block_tables
    loader.export(
  File "/usr/local/lib/python3.10/site-packages/mage_ai/io/bigquery.py", line 323, in export
    __process(database=database)
  File "/usr/local/lib/python3.10/site-packages/mage_ai/io/bigquery.py", line 296, in __process
    column_types = self.get_column_types(schema, table_name)
  File "/usr/local/lib/python3.10/site-packages/mage_ai/io/bigquery.py", line 93, in get_column_types
    for col, col_type in results:
  File "/usr/local/lib/python3.10/site-packages/google/cloud/bigquery/job/query.py", line 1994, in __iter__
    return iter(self.result())
  File "/usr/local/lib/python3.10/site-packages/google/cloud/bigquery/job/query.py", line 1595, in result
    do_get_result()
  File "/usr/local/lib/python3.10/site-packages/google/api_core/retry.py", line 372, in retry_wrapped_func
    return retry_target(
  File "/usr/local/lib/python3.10/site-packages/google/api_core/retry.py", line 207, in retry_target
    result = target()
  File "/usr/local/lib/python3.10/site-packages/google/cloud/bigquery/job/query.py", line 1584, in do_get_result
    super(QueryJob, self).result(retry=retry, timeout=timeout)
  File "/usr/local/lib/python3.10/site-packages/google/cloud/bigquery/job/base.py", line 952, in result
    return super(_AsyncJob, self).result(timeout=timeout, **kwargs)
  File "/usr/local/lib/python3.10/site-packages/google/api_core/future/polling.py", line 261, in result
    raise self._exception
google.api_core.exceptions.NotFound: 404 Not found: Dataset snappy-catcher-418306:employee_data was not found in location EU

Location: EU
Job ID: 1cdc8153-6ebc-4d0d-8ff9-54989e955a80

